2024-07-19 23:11:14,955 INFO    MainThread:4532 [internal.py:wandb_internal():93] W&B internal server running at pid: 4532, started at: 2024-07-19 23:11:14.955282
2024-07-19 23:11:14,956 INFO    WriterThread:4532 [datastore.py:open_for_write():75] open: D:\hammer\folder\flood_unet\wandb\run-20240719_231113-2pscqgu8\run-2pscqgu8.wandb
2024-07-19 23:11:14,959 DEBUG   SenderThread:4532 [sender.py:send():236] send: header
2024-07-19 23:11:14,959 DEBUG   SenderThread:4532 [sender.py:send():236] send: run
2024-07-19 23:11:43,565 DEBUG   HandlerThread:4532 [handler.py:handle_request():140] handle_request: shutdown
2024-07-19 23:11:43,567 INFO    HandlerThread:4532 [handler.py:finish():806] shutting down handler
2024-07-19 23:11:44,177 INFO    WriterThread:4532 [datastore.py:close():279] close: D:\hammer\folder\flood_unet\wandb\run-20240719_231113-2pscqgu8\run-2pscqgu8.wandb
2024-07-19 23:11:49,007 ERROR   SenderThread:4532 [retry.py:__call__():132] Retry attempt failed:
Traceback (most recent call last):
  File "C:\Users\Administrator\.conda\envs\torch\lib\site-packages\urllib3\connection.py", line 175, in _new_conn
    (self._dns_host, self.port), self.timeout, **extra_kw
  File "C:\Users\Administrator\.conda\envs\torch\lib\site-packages\urllib3\util\connection.py", line 95, in create_connection
    raise err
  File "C:\Users\Administrator\.conda\envs\torch\lib\site-packages\urllib3\util\connection.py", line 85, in create_connection
    sock.connect(sa)
socket.timeout: timed out

During handling of the above exception, another exception occurred:

Traceback (most recent call last):
  File "C:\Users\Administrator\.conda\envs\torch\lib\site-packages\urllib3\connectionpool.py", line 710, in urlopen
    chunked=chunked,
  File "C:\Users\Administrator\.conda\envs\torch\lib\site-packages\urllib3\connectionpool.py", line 386, in _make_request
    self._validate_conn(conn)
  File "C:\Users\Administrator\.conda\envs\torch\lib\site-packages\urllib3\connectionpool.py", line 1040, in _validate_conn
    conn.connect()
  File "C:\Users\Administrator\.conda\envs\torch\lib\site-packages\urllib3\connection.py", line 358, in connect
    self.sock = conn = self._new_conn()
  File "C:\Users\Administrator\.conda\envs\torch\lib\site-packages\urllib3\connection.py", line 182, in _new_conn
    % (self.host, self.timeout),
urllib3.exceptions.ConnectTimeoutError: (<urllib3.connection.HTTPSConnection object at 0x0000021EEAA17470>, 'Connection to api.wandb.ai timed out. (connect timeout=10)')

During handling of the above exception, another exception occurred:

Traceback (most recent call last):
  File "C:\Users\Administrator\.conda\envs\torch\lib\site-packages\requests\adapters.py", line 450, in send
    timeout=timeout
  File "C:\Users\Administrator\.conda\envs\torch\lib\site-packages\urllib3\connectionpool.py", line 786, in urlopen
    method, url, error=e, _pool=self, _stacktrace=sys.exc_info()[2]
  File "C:\Users\Administrator\.conda\envs\torch\lib\site-packages\urllib3\util\retry.py", line 592, in increment
    raise MaxRetryError(_pool, url, error or ResponseError(cause))
urllib3.exceptions.MaxRetryError: HTTPSConnectionPool(host='api.wandb.ai', port=443): Max retries exceeded with url: /graphql (Caused by ConnectTimeoutError(<urllib3.connection.HTTPSConnection object at 0x0000021EEAA17470>, 'Connection to api.wandb.ai timed out. (connect timeout=10)'))

During handling of the above exception, another exception occurred:

Traceback (most recent call last):
  File "C:\Users\Administrator\.conda\envs\torch\lib\site-packages\wandb\sdk\lib\retry.py", line 108, in __call__
    result = self._call_fn(*args, **kwargs)
  File "C:\Users\Administrator\.conda\envs\torch\lib\site-packages\wandb\sdk\internal\internal_api.py", line 158, in execute
    return self.client.execute(*args, **kwargs)
  File "C:\Users\Administrator\.conda\envs\torch\lib\site-packages\wandb\vendor\gql-0.2.0\wandb_gql\client.py", line 52, in execute
    result = self._get_result(document, *args, **kwargs)
  File "C:\Users\Administrator\.conda\envs\torch\lib\site-packages\wandb\vendor\gql-0.2.0\wandb_gql\client.py", line 60, in _get_result
    return self.transport.execute(document, *args, **kwargs)
  File "C:\Users\Administrator\.conda\envs\torch\lib\site-packages\wandb\vendor\gql-0.2.0\wandb_gql\transport\requests.py", line 38, in execute
    request = requests.post(self.url, **post_args)
  File "C:\Users\Administrator\.conda\envs\torch\lib\site-packages\requests\api.py", line 117, in post
    return request('post', url, data=data, json=json, **kwargs)
  File "C:\Users\Administrator\.conda\envs\torch\lib\site-packages\requests\api.py", line 61, in request
    return session.request(method=method, url=url, **kwargs)
  File "C:\Users\Administrator\.conda\envs\torch\lib\site-packages\requests\sessions.py", line 529, in request
    resp = self.send(prep, **send_kwargs)
  File "C:\Users\Administrator\.conda\envs\torch\lib\site-packages\requests\sessions.py", line 645, in send
    r = adapter.send(request, **kwargs)
  File "C:\Users\Administrator\.conda\envs\torch\lib\site-packages\requests\adapters.py", line 507, in send
    raise ConnectTimeout(e, request=request)
requests.exceptions.ConnectTimeout: HTTPSConnectionPool(host='api.wandb.ai', port=443): Max retries exceeded with url: /graphql (Caused by ConnectTimeoutError(<urllib3.connection.HTTPSConnection object at 0x0000021EEAA17470>, 'Connection to api.wandb.ai timed out. (connect timeout=10)'))
