2024-07-20 00:22:14,634 INFO    MainThread:13368 [internal.py:wandb_internal():93] W&B internal server running at pid: 13368, started at: 2024-07-20 00:22:14.634049
2024-07-20 00:22:14,636 INFO    WriterThread:13368 [datastore.py:open_for_write():75] open: D:\hammer\folder\flood_unet\wandb\offline-run-20240720_002213-1332lfsb\run-1332lfsb.wandb
2024-07-20 00:22:14,636 DEBUG   HandlerThread:13368 [handler.py:handle_request():140] handle_request: run_start
2024-07-20 00:22:14,668 DEBUG   HandlerThread:13368 [meta.py:__init__():35] meta init
2024-07-20 00:22:14,669 DEBUG   HandlerThread:13368 [meta.py:__init__():49] meta init done
2024-07-20 00:22:14,669 DEBUG   HandlerThread:13368 [meta.py:probe():209] probe
2024-07-20 00:22:14,719 DEBUG   HandlerThread:13368 [git.py:repo():29] git repository is invalid
2024-07-20 00:22:14,719 DEBUG   HandlerThread:13368 [meta.py:_save_pip():53] save pip
2024-07-20 00:22:14,720 DEBUG   HandlerThread:13368 [meta.py:_save_pip():67] save pip done
2024-07-20 00:22:14,720 DEBUG   HandlerThread:13368 [meta.py:_save_conda():74] save conda
2024-07-20 00:22:25,958 DEBUG   HandlerThread:13368 [meta.py:_save_conda():84] save conda done
2024-07-20 00:22:25,958 DEBUG   HandlerThread:13368 [meta.py:probe():247] probe done
2024-07-20 00:24:02,812 WARNING MainThread:13368 [internal.py:wandb_internal():153] Internal process interrupt: 1
2024-07-20 00:24:04,531 WARNING MainThread:13368 [internal.py:wandb_internal():153] Internal process interrupt: 2
2024-07-20 00:24:04,531 ERROR   MainThread:13368 [internal.py:wandb_internal():156] Internal process interrupted.
2024-07-20 00:24:04,559 INFO    SenderThread:13368 [sender.py:finish():1114] shutting down sender
2024-07-20 00:24:04,873 INFO    WriterThread:13368 [datastore.py:close():279] close: D:\hammer\folder\flood_unet\wandb\offline-run-20240720_002213-1332lfsb\run-1332lfsb.wandb
2024-07-20 00:24:04,873 INFO    HandlerThread:13368 [handler.py:finish():806] shutting down handler
2024-07-20 00:24:04,873 INFO    MainThread:13368 [internal.py:handle_exit():80] Internal process exited
