Using device: cuda:1
Epoch 1/50
  0%|                                                                                                                                     | 0/210 [00:09<?, ?it/s]
Traceback (most recent call last):
  File "train.py", line 212, in <module>
    train(net, args)
  File "train.py", line 72, in train
    output = net(t1_img, t2_img)
  File "/home_ext/whm_ext/miniconda3/envs/camera/lib/python3.8/site-packages/torch/nn/modules/module.py", line 1051, in _call_impl
    return forward_call(*input, **kwargs)
  File "/home_ext/whm_ext/miniconda3/envs/camera/lib/python3.8/site-packages/torch/nn/parallel/data_parallel.py", line 168, in forward
    outputs = self.parallel_apply(replicas, inputs, kwargs)
  File "/home_ext/whm_ext/miniconda3/envs/camera/lib/python3.8/site-packages/torch/nn/parallel/data_parallel.py", line 178, in parallel_apply
    return parallel_apply(replicas, inputs, kwargs, self.device_ids[:len(replicas)])
  File "/home_ext/whm_ext/miniconda3/envs/camera/lib/python3.8/site-packages/torch/nn/parallel/parallel_apply.py", line 86, in parallel_apply
    output.reraise()
  File "/home_ext/whm_ext/miniconda3/envs/camera/lib/python3.8/site-packages/torch/_utils.py", line 425, in reraise
    raise self.exc_type(msg)
RuntimeError: Caught RuntimeError in replica 0 on device 1.
Original Traceback (most recent call last):
  File "/home_ext/whm_ext/miniconda3/envs/camera/lib/python3.8/site-packages/torch/nn/parallel/parallel_apply.py", line 61, in _worker
    output = module(*input, **kwargs)
  File "/home_ext/whm_ext/miniconda3/envs/camera/lib/python3.8/site-packages/torch/nn/modules/module.py", line 1051, in _call_impl
    return forward_call(*input, **kwargs)
  File "/home_ext/whm_ext/hcq/7/flood_unet/network/model.py", line 77, in forward
    s2_feature = self.s2_stream(t2_img)
  File "/home_ext/whm_ext/miniconda3/envs/camera/lib/python3.8/site-packages/torch/nn/modules/module.py", line 1051, in _call_impl
    return forward_call(*input, **kwargs)
  File "/home_ext/whm_ext/hcq/7/flood_unet/network/reunet.py", line 110, in forward
    x10 = self.up_residual_conv3(x9)
  File "/home_ext/whm_ext/miniconda3/envs/camera/lib/python3.8/site-packages/torch/nn/modules/module.py", line 1051, in _call_impl
    return forward_call(*input, **kwargs)
  File "/home_ext/whm_ext/hcq/7/flood_unet/network/reunet.py", line 28, in forward
    return self.conv_block(x) + self.conv_skip(x)
  File "/home_ext/whm_ext/miniconda3/envs/camera/lib/python3.8/site-packages/torch/nn/modules/module.py", line 1051, in _call_impl
    return forward_call(*input, **kwargs)
  File "/home_ext/whm_ext/miniconda3/envs/camera/lib/python3.8/site-packages/torch/nn/modules/container.py", line 139, in forward
    input = module(input)
  File "/home_ext/whm_ext/miniconda3/envs/camera/lib/python3.8/site-packages/torch/nn/modules/module.py", line 1051, in _call_impl
    return forward_call(*input, **kwargs)
  File "/home_ext/whm_ext/miniconda3/envs/camera/lib/python3.8/site-packages/torch/nn/modules/conv.py", line 443, in forward
    return self._conv_forward(input, self.weight, self.bias)
  File "/home_ext/whm_ext/miniconda3/envs/camera/lib/python3.8/site-packages/torch/nn/modules/conv.py", line 439, in _conv_forward
    return F.conv2d(input, weight, bias, self.stride,
RuntimeError: Unable to find a valid cuDNN algorithm to run convolution