Using device: cuda:3
Epoch 1/50
  0%|                                                                                                                            | 0/656 [00:01<?, ?it/s]
Traceback (most recent call last):
  File "train.py", line 210, in <module>
    train(net, args)
  File "train.py", line 70, in train
    output = net(t1_img, t2_img)
  File "/home_ext/whm_ext/miniconda3/envs/camera/lib/python3.8/site-packages/torch/nn/modules/module.py", line 1051, in _call_impl
    return forward_call(*input, **kwargs)
  File "/home_ext/whm_ext/hcq/7/flood_unet/network/model.py", line 81, in forward
    out = self.out_conv(fusion)
  File "/home_ext/whm_ext/miniconda3/envs/camera/lib/python3.8/site-packages/torch/nn/modules/module.py", line 1051, in _call_impl
    return forward_call(*input, **kwargs)
  File "/home_ext/whm_ext/hcq/7/flood_unet/network/model.py", line 240, in forward
    x = self.conv(x)
  File "/home_ext/whm_ext/miniconda3/envs/camera/lib/python3.8/site-packages/torch/nn/modules/module.py", line 1051, in _call_impl
    return forward_call(*input, **kwargs)
  File "/home_ext/whm_ext/miniconda3/envs/camera/lib/python3.8/site-packages/torch/nn/modules/conv.py", line 443, in forward
    return self._conv_forward(input, self.weight, self.bias)
  File "/home_ext/whm_ext/miniconda3/envs/camera/lib/python3.8/site-packages/torch/nn/modules/conv.py", line 439, in _conv_forward
    return F.conv2d(input, weight, bias, self.stride,
RuntimeError: Given groups=1, weight of size [1, 128, 1, 1], expected input[16, 384, 256, 256] to have 128 channels, but got 384 channels instead